Workbook

Sheet Instructions
B2: DRAFT Attachment 1 - NCCS Pricing Template
B4: Instructions for Completing the "Labor Rates" Tab: Contractor must complete all yellow fields. The rates proposed in this tab will be incorporated into the contract for the specified period. The Government will use these rates, applied to the evaluation quantities, to calculate the total evaluated price for best value tradeoff.
B6: (2). "Labor Rate" tab: Contractor must complete all yellow fields as follows: (1) Cell B4: Enter the escalation factor that will be applied to out-year pricing. (2) Cell B5: Enter the "Top Secret" rate multiplier, which will be applied to the "SBU / Secret / Remote" rate to determine the "Top Secret" rate. (3) All other yellow fields: Propose a rate for each labor category listed.
B7: All yellow shaded areas must be completed.

Sheet Labor Rates
A3: Factors Applied | B3: Proposed Percentage
A4: Escalation Rate | B4: 0
A5: Premium for Top Secret level | B5: 0
B7: Base Period - 09/01/2026 - 08/31/2027 | I7: Option 1 - 09/01/2027 - 08/31/2028 | P7: Option 2 - 09/01/2028 - 08/31/2029 | W7: Option 3 - 09/01/2029 - 08/31/2030 | AD7: Option 4 - 09/01/2030 - 08/31/2031
B8: Washington DC | D8: Chandler, AZ | F8: Sennis, MS | I8: Washington DC | K8: Chandler, AZ | M8: Sennis, MS | P8: Washington DC | R8: Chandler, AZ | T8: Sennis, MS | W8: Washington DC | Y8: Chandler, AZ | AA8: Sennis, MS | AD8: Washington DC | AF8: Chandler, AZ | AH8: Sennis, MS
B9: SBU / Secret / Remote | C9: TS_SCI and SAP | D9: SBU / Secret / Remote | E9: TS_SCI and SAP | F9: SBU / Secret / Remote | G9: TS_SCI and SAP | I9: SBU / Secret / Remote | J9: TS_SCI and SAP | K9: SBU / Secret / Remote | L9: TS_SCI and SAP | M9: SBU / Secret / Remote | N9: TS_SCI and SAP | P9: SBU / Secret / Remote | Q9: TS_SCI and SAP | R9: SBU / Secret / Remote | S9: TS_SCI and SAP | T9: SBU / Secret / Remote | U9: TS_SCI and SAP | W9: SBU / Secret / Remote | X9: TS_SCI and SAP | Y9: SBU / Secret / Remote | Z9: TS_SCI and SAP | AA9: SBU / Secret / Remote | AB9: TS_SCI and SAP | AD9: SBU / Secret / Remote | AE9: TS_SCI and SAP | AF9: SBU / Secret / Remote | AG9: TS_SCI and SAP | AH9: SBU / Secret / Remote | AI9: TS_SCI and SAP
A10: Task 1 - Contract Management
A11: Program Manager | B11: 0 | C11: =+B11+('Labor Rates'!$B$5*B11) -> 0 | D11: 0 | E11: =+D11+('Labor Rates'!$B$5*D11) -> 0 | F11: 0 | G11: =+F11+('Labor Rates'!$B$5*F11) -> 0 | I11: =SUM(B11*'Labor Rates'!$B$4+B11) -> 0 | J11: =SUM(C11*'Labor Rates'!$B$4+C11) -> 0 | K11: =SUM(D11*'Labor Rates'!$B$4+D11) -> 0 | L11: =SUM(E11*'Labor Rates'!$B$4+E11) -> 0 | M11: =SUM(F11*'Labor Rates'!$B$4+F11) -> 0 | N11: =SUM(G11*'Labor Rates'!$B$4+G11) -> 0 | P11: =SUM(I11*'Labor Rates'!$B$4+I11) -> 0 | Q11: =SUM(J11*'Labor Rates'!$B$4+J11) -> 0 | R11: =SUM(K11*'Labor Rates'!$B$4+K11) -> 0 | S11: =SUM(L11*'Labor Rates'!$B$4+L11) -> 0 | T11: =SUM(M11*'Labor Rates'!$B$4+M11) -> 0 | U11: =SUM(N11*'Labor Rates'!$B$4+N11) -> 0 | W11: =SUM(P11*'Labor Rates'!$B$4+P11) -> 0 | X11: =SUM(Q11*'Labor Rates'!$B$4+Q11) -> 0 | Y11: =SUM(R11*'Labor Rates'!$B$4+R11) -> 0 | Z11: =SUM(S11*'Labor Rates'!$B$4+S11) -> 0 | AA11: =SUM(T11*'Labor Rates'!$B$4+T11) -> 0 | AB11: =SUM(U11*'Labor Rates'!$B$4+U11) -> 0 | AD11: =SUM(W11*'Labor Rates'!$B$4+W11) -> 0 | AE11: =SUM(X11*'Labor Rates'!$B$4+X11) -> 0 | AF11: =SUM(Y11*'Labor Rates'!$B$4+Y11) -> 0 | AG11: =SUM(Z11*'Labor Rates'!$B$4+Z11) -> 0 | AH11: =SUM(AA11*'Labor Rates'!$B$4+AA11) -> 0 | AI11: =SUM(AB11*'Labor Rates'!$B$4+AB11) -> 0
A12: Deputy Program Manager | B12: 0 | C12: =+B12+('Labor Rates'!$B$5*B12) -> 0 | D12: 0 | E12: =+D12+('Labor Rates'!$B$5*D12) -> 0 | F12: 0 | G12: =+F12+('Labor Rates'!$B$5*F12) -> 0 | I12: =SUM(B12*'Labor Rates'!$B$4+B12) -> 0 | J12: =SUM(C12*'Labor Rates'!$B$4+C12) -> 0 | K12: =SUM(D12*'Labor Rates'!$B$4+D12) -> 0 | L12: =SUM(E12*'Labor Rates'!$B$4+E12) -> 0 | M12: =SUM(F12*'Labor Rates'!$B$4+F12) -> 0 | N12: =SUM(G12*'Labor Rates'!$B$4+G12) -> 0 | P12: =SUM(I12*'Labor Rates'!$B$4+I12) -> 0 | Q12: =SUM(J12*'Labor Rates'!$B$4+J12) -> 0 | R12: =SUM(K12*'Labor Rates'!$B$4+K12) -> 0 | S12: =SUM(L12*'Labor Rates'!$B$4+L12) -> 0 | T12: =SUM(M12*'Labor Rates'!$B$4+M12) -> 0 | U12: =SUM(N12*'Labor Rates'!$B$4+N12) -> 0 | W12: =SUM(P12*'Labor Rates'!$B$4+P12) -> 0 | X12: =SUM(Q12*'Labor Rates'!$B$4+Q12) -> 0 | Y12: =SUM(R12*'Labor Rates'!$B$4+R12) -> 0 | Z12: =SUM(S12*'Labor Rates'!$B$4+S12) -> 0 | AA12: =SUM(T12*'Labor Rates'!$B$4+T12) -> 0 | AB12: =SUM(U12*'Labor Rates'!$B$4+U12) -> 0 | AD12: =SUM(W12*'Labor Rates'!$B$4+W12) -> 0 | AE12: =SUM(X12*'Labor Rates'!$B$4+X12) -> 0 | AF12: =SUM(Y12*'Labor Rates'!$B$4+Y12) -> 0 | AG12: =SUM(Z12*'Labor Rates'!$B$4+Z12) -> 0 | AH12: =SUM(AA12*'Labor Rates'!$B$4+AA12) -> 0 | AI12: =SUM(AB12*'Labor Rates'!$B$4+AB12) -> 0
A13: Task 2 - Capability Development and Improvement
A14: Business Analyst - Senior Level | B14: 0 | C14: =+B14+('Labor Rates'!$B$5*B14) -> 0 | D14: 0 | E14: =+D14+('Labor Rates'!$B$5*D14) -> 0 | F14: 0 | G14: =+F14+('Labor Rates'!$B$5*F14) -> 0 | I14: =SUM(B14*'Labor Rates'!$B$4+B14) -> 0 | J14: =SUM(C14*'Labor Rates'!$B$4+C14) -> 0 | K14: =SUM(D14*'Labor Rates'!$B$4+D14) -> 0 | L14: =SUM(E14*'Labor Rates'!$B$4+E14) -> 0 | M14: =SUM(F14*'Labor Rates'!$B$4+F14) -> 0 | N14: =SUM(G14*'Labor Rates'!$B$4+G14) -> 0 | P14: =SUM(I14*'Labor Rates'!$B$4+I14) -> 0 | Q14: =SUM(J14*'Labor Rates'!$B$4+J14) -> 0 | R14: =SUM(K14*'Labor Rates'!$B$4+K14) -> 0 | S14: =SUM(L14*'Labor Rates'!$B$4+L14) -> 0 | T14: =SUM(M14*'Labor Rates'!$B$4+M14) -> 0 | U14: =SUM(N14*'Labor Rates'!$B$4+N14) -> 0 | W14: =SUM(P14*'Labor Rates'!$B$4+P14) -> 0 | X14: =SUM(Q14*'Labor Rates'!$B$4+Q14) -> 0 | Y14: =SUM(R14*'Labor Rates'!$B$4+R14) -> 0 | Z14: =SUM(S14*'Labor Rates'!$B$4+S14) -> 0 | AA14: =SUM(T14*'Labor Rates'!$B$4+T14) -> 0 | AB14: =SUM(U14*'Labor Rates'!$B$4+U14) -> 0 | AD14: =SUM(W14*'Labor Rates'!$B$4+W14) -> 0 | AE14: =SUM(X14*'Labor Rates'!$B$4+X14) -> 0 | AF14: =SUM(Y14*'Labor Rates'!$B$4+Y14) -> 0 | AG14: =SUM(Z14*'Labor Rates'!$B$4+Z14) -> 0 | AH14: =SUM(AA14*'Labor Rates'!$B$4+AA14) -> 0 | AI14: =SUM(AB14*'Labor Rates'!$B$4+AB14) -> 0
A15: Business Analyst - Mid-Level | B15: 0 | C15: =+B15+('Labor Rates'!$B$5*B15) -> 0 | D15: 0 | E15: =+D15+('Labor Rates'!$B$5*D15) -> 0 | F15: 0 | G15: =+F15+('Labor Rates'!$B$5*F15) -> 0 | I15: =SUM(B15*'Labor Rates'!$B$4+B15) -> 0 | J15: =SUM(C15*'Labor Rates'!$B$4+C15) -> 0 | K15: =SUM(D15*'Labor Rates'!$B$4+D15) -> 0 | L15: =SUM(E15*'Labor Rates'!$B$4+E15) -> 0 | M15: =SUM(F15*'Labor Rates'!$B$4+F15) -> 0 | N15: =SUM(G15*'Labor Rates'!$B$4+G15) -> 0 | P15: =SUM(I15*'Labor Rates'!$B$4+I15) -> 0 | Q15: =SUM(J15*'Labor Rates'!$B$4+J15) -> 0 | R15: =SUM(K15*'Labor Rates'!$B$4+K15) -> 0 | S15: =SUM(L15*'Labor Rates'!$B$4+L15) -> 0 | T15: =SUM(M15*'Labor Rates'!$B$4+M15) -> 0 | U15: =SUM(N15*'Labor Rates'!$B$4+N15) -> 0 | W15: =SUM(P15*'Labor Rates'!$B$4+P15) -> 0 | X15: =SUM(Q15*'Labor Rates'!$B$4+Q15) -> 0 | Y15: =SUM(R15*'Labor Rates'!$B$4+R15) -> 0 | Z15: =SUM(S15*'Labor Rates'!$B$4+S15) -> 0 | AA15: =SUM(T15*'Labor Rates'!$B$4+T15) -> 0 | AB15: =SUM(U15*'Labor Rates'!$B$4+U15) -> 0 | AD15: =SUM(W15*'Labor Rates'!$B$4+W15) -> 0 | AE15: =SUM(X15*'Labor Rates'!$B$4+X15) -> 0 | AF15: =SUM(Y15*'Labor Rates'!$B$4+Y15) -> 0 | AG15: =SUM(Z15*'Labor Rates'!$B$4+Z15) -> 0 | AH15: =SUM(AA15*'Labor Rates'!$B$4+AA15) -> 0 | AI15: =SUM(AB15*'Labor Rates'!$B$4+AB15) -> 0
A16: Business Analyst - Junior Level | B16: 0 | C16: =+B16+('Labor Rates'!$B$5*B16) -> 0 | D16: 0 | E16: =+D16+('Labor Rates'!$B$5*D16) -> 0 | F16: 0 | G16: =+F16+('Labor Rates'!$B$5*F16) -> 0 | I16: =SUM(B16*'Labor Rates'!$B$4+B16) -> 0 | J16: =SUM(C16*'Labor Rates'!$B$4+C16) -> 0 | K16: =SUM(D16*'Labor Rates'!$B$4+D16) -> 0 | L16: =SUM(E16*'Labor Rates'!$B$4+E16) -> 0 | M16: =SUM(F16*'Labor Rates'!$B$4+F16) -> 0 | N16: =SUM(G16*'Labor Rates'!$B$4+G16) -> 0 | P16: =SUM(I16*'Labor Rates'!$B$4+I16) -> 0 | Q16: =SUM(J16*'Labor Rates'!$B$4+J16) -> 0 | R16: =SUM(K16*'Labor Rates'!$B$4+K16) -> 0 | S16: =SUM(L16*'Labor Rates'!$B$4+L16) -> 0 | T16: =SUM(M16*'Labor Rates'!$B$4+M16) -> 0 | U16: =SUM(N16*'Labor Rates'!$B$4+N16) -> 0 | W16: =SUM(P16*'Labor Rates'!$B$4+P16) -> 0 | X16: =SUM(Q16*'Labor Rates'!$B$4+Q16) -> 0 | Y16: =SUM(R16*'Labor Rates'!$B$4+R16) -> 0 | Z16: =SUM(S16*'Labor Rates'!$B$4+S16) -> 0 | AA16: =SUM(T16*'Labor Rates'!$B$4+T16) -> 0 | AB16: =SUM(U16*'Labor Rates'!$B$4+U16) -> 0 | AD16: =SUM(W16*'Labor Rates'!$B$4+W16) -> 0 | AE16: =SUM(X16*'Labor Rates'!$B$4+X16) -> 0 | AF16: =SUM(Y16*'Labor Rates'!$B$4+Y16) -> 0 | AG16: =SUM(Z16*'Labor Rates'!$B$4+Z16) -> 0 | AH16: =SUM(AA16*'Labor Rates'!$B$4+AA16) -> 0 | AI16: =SUM(AB16*'Labor Rates'!$B$4+AB16) -> 0
A17: Business Intelligence Analyst - Senior Level | B17: 0 | C17: =+B17+('Labor Rates'!$B$5*B17) -> 0 | D17: 0 | E17: =+D17+('Labor Rates'!$B$5*D17) -> 0 | F17: 0 | G17: =+F17+('Labor Rates'!$B$5*F17) -> 0 | I17: =SUM(B17*'Labor Rates'!$B$4+B17) -> 0 | J17: =SUM(C17*'Labor Rates'!$B$4+C17) -> 0 | K17: =SUM(D17*'Labor Rates'!$B$4+D17) -> 0 | L17: =SUM(E17*'Labor Rates'!$B$4+E17) -> 0 | M17: =SUM(F17*'Labor Rates'!$B$4+F17) -> 0 | N17: =SUM(G17*'Labor Rates'!$B$4+G17) -> 0 | P17: =SUM(I17*'Labor Rates'!$B$4+I17) -> 0 | Q17: =SUM(J17*'Labor Rates'!$B$4+J17) -> 0 | R17: =SUM(K17*'Labor Rates'!$B$4+K17) -> 0 | S17: =SUM(L17*'Labor Rates'!$B$4+L17) -> 0 | T17: =SUM(M17*'Labor Rates'!$B$4+M17) -> 0 | U17: =SUM(N17*'Labor Rates'!$B$4+N17) -> 0 | W17: =SUM(P17*'Labor Rates'!$B$4+P17) -> 0 | X17: =SUM(Q17*'Labor Rates'!$B$4+Q17) -> 0 | Y17: =SUM(R17*'Labor Rates'!$B$4+R17) -> 0 | Z17: =SUM(S17*'Labor Rates'!$B$4+S17) -> 0 | AA17: =SUM(T17*'Labor Rates'!$B$4+T17) -> 0 | AB17: =SUM(U17*'Labor Rates'!$B$4+U17) -> 0 | AD17: =SUM(W17*'Labor Rates'!$B$4+W17) -> 0 | AE17: =SUM(X17*'Labor Rates'!$B$4+X17) -> 0 | AF17: =SUM(Y17*'Labor Rates'!$B$4+Y17) -> 0 | AG17: =SUM(Z17*'Labor Rates'!$B$4+Z17) -> 0 | AH17: =SUM(AA17*'Labor Rates'!$B$4+AA17) -> 0 | AI17: =SUM(AB17*'Labor Rates'!$B$4+AB17) -> 0
A18: Business Intelligence Analyst - Mid-Level | B18: 0 | C18: =+B18+('Labor Rates'!$B$5*B18) -> 0 | D18: 0 | E18: =+D18+('Labor Rates'!$B$5*D18) -> 0 | F18: 0 | G18: =+F18+('Labor Rates'!$B$5*F18) -> 0 | I18: =SUM(B18*'Labor Rates'!$B$4+B18) -> 0 | J18: =SUM(C18*'Labor Rates'!$B$4+C18) -> 0 | K18: =SUM(D18*'Labor Rates'!$B$4+D18) -> 0 | L18: =SUM(E18*'Labor Rates'!$B$4+E18) -> 0 | M18: =SUM(F18*'Labor Rates'!$B$4+F18) -> 0 | N18: =SUM(G18*'Labor Rates'!$B$4+G18) -> 0 | P18: =SUM(I18*'Labor Rates'!$B$4+I18) -> 0 | Q18: =SUM(J18*'Labor Rates'!$B$4+J18) -> 0 | R18: =SUM(K18*'Labor Rates'!$B$4+K18) -> 0 | S18: =SUM(L18*'Labor Rates'!$B$4+L18) -> 0 | T18: =SUM(M18*'Labor Rates'!$B$4+M18) -> 0 | U18: =SUM(N18*'Labor Rates'!$B$4+N18) -> 0 | W18: =SUM(P18*'Labor Rates'!$B$4+P18) -> 0 | X18: =SUM(Q18*'Labor Rates'!$B$4+Q18) -> 0 | Y18: =SUM(R18*'Labor Rates'!$B$4+R18) -> 0 | Z18: =SUM(S18*'Labor Rates'!$B$4+S18) -> 0 | AA18: =SUM(T18*'Labor Rates'!$B$4+T18) -> 0 | AB18: =SUM(U18*'Labor Rates'!$B$4+U18) -> 0 | AD18: =SUM(W18*'Labor Rates'!$B$4+W18) -> 0 | AE18: =SUM(X18*'Labor Rates'!$B$4+X18) -> 0 | AF18: =SUM(Y18*'Labor Rates'!$B$4+Y18) -> 0 | AG18: =SUM(Z18*'Labor Rates'!$B$4+Z18) -> 0 | AH18: =SUM(AA18*'Labor Rates'!$B$4+AA18) -> 0 | AI18: =SUM(AB18*'Labor Rates'!$B$4+AB18) -> 0
A19: Business Intelligence Analyst - Junior Level | B19: 0 | C19: =+B19+('Labor Rates'!$B$5*B19) -> 0 | D19: 0 | E19: =+D19+('Labor Rates'!$B$5*D19) -> 0 | F19: 0 | G19: =+F19+('Labor Rates'!$B$5*F19) -> 0 | I19: =SUM(B19*'Labor Rates'!$B$4+B19) -> 0 | J19: =SUM(C19*'Labor Rates'!$B$4+C19) -> 0 | K19: =SUM(D19*'Labor Rates'!$B$4+D19) -> 0 | L19: =SUM(E19*'Labor Rates'!$B$4+E19) -> 0 | M19: =SUM(F19*'Labor Rates'!$B$4+F19) -> 0 | N19: =SUM(G19*'Labor Rates'!$B$4+G19) -> 0 | P19: =SUM(I19*'Labor Rates'!$B$4+I19) -> 0 | Q19: =SUM(J19*'Labor Rates'!$B$4+J19) -> 0 | R19: =SUM(K19*'Labor Rates'!$B$4+K19) -> 0 | S19: =SUM(L19*'Labor Rates'!$B$4+L19) -> 0 | T19: =SUM(M19*'Labor Rates'!$B$4+M19) -> 0 | U19: =SUM(N19*'Labor Rates'!$B$4+N19) -> 0 | W19: =SUM(P19*'Labor Rates'!$B$4+P19) -> 0 | X19: =SUM(Q19*'Labor Rates'!$B$4+Q19) -> 0 | Y19: =SUM(R19*'Labor Rates'!$B$4+R19) -> 0 | Z19: =SUM(S19*'Labor Rates'!$B$4+S19) -> 0 | AA19: =SUM(T19*'Labor Rates'!$B$4+T19) -> 0 | AB19: =SUM(U19*'Labor Rates'!$B$4+U19) -> 0 | AD19: =SUM(W19*'Labor Rates'!$B$4+W19) -> 0 | AE19: =SUM(X19*'Labor Rates'!$B$4+X19) -> 0 | AF19: =SUM(Y19*'Labor Rates'!$B$4+Y19) -> 0 | AG19: =SUM(Z19*'Labor Rates'!$B$4+Z19) -> 0 | AH19: =SUM(AA19*'Labor Rates'!$B$4+AA19) -> 0 | AI19: =SUM(AB19*'Labor Rates'!$B$4+AB19) -> 0
A20: Document Management Specialist - Senior Level | B20: 0 | C20: =+B20+('Labor Rates'!$B$5*B20) -> 0 | D20: 0 | E20: =+D20+('Labor Rates'!$B$5*D20) -> 0 | F20: 0 | G20: =+F20+('Labor Rates'!$B$5*F20) -> 0 | I20: =SUM(B20*'Labor Rates'!$B$4+B20) -> 0 | J20: =SUM(C20*'Labor Rates'!$B$4+C20) -> 0 | K20: =SUM(D20*'Labor Rates'!$B$4+D20) -> 0 | L20: =SUM(E20*'Labor Rates'!$B$4+E20) -> 0 | M20: =SUM(F20*'Labor Rates'!$B$4+F20) -> 0 | N20: =SUM(G20*'Labor Rates'!$B$4+G20) -> 0 | P20: =SUM(I20*'Labor Rates'!$B$4+I20) -> 0 | Q20: =SUM(J20*'Labor Rates'!$B$4+J20) -> 0 | R20: =SUM(K20*'Labor Rates'!$B$4+K20) -> 0 | S20: =SUM(L20*'Labor Rates'!$B$4+L20) -> 0 | T20: =SUM(M20*'Labor Rates'!$B$4+M20) -> 0 | U20: =SUM(N20*'Labor Rates'!$B$4+N20) -> 0 | W20: =SUM(P20*'Labor Rates'!$B$4+P20) -> 0 | X20: =SUM(Q20*'Labor Rates'!$B$4+Q20) -> 0 | Y20: =SUM(R20*'Labor Rates'!$B$4+R20) -> 0 | Z20: =SUM(S20*'Labor Rates'!$B$4+S20) -> 0 | AA20: =SUM(T20*'Labor Rates'!$B$4+T20) -> 0 | AB20: =SUM(U20*'Labor Rates'!$B$4+U20) -> 0 | AD20: =SUM(W20*'Labor Rates'!$B$4+W20) -> 0 | AE20: =SUM(X20*'Labor Rates'!$B$4+X20) -> 0 | AF20: =SUM(Y20*'Labor Rates'!$B$4+Y20) -> 0 | AG20: =SUM(Z20*'Labor Rates'!$B$4+Z20) -> 0 | AH20: =SUM(AA20*'Labor Rates'!$B$4+AA20) -> 0 | AI20: =SUM(AB20*'Labor Rates'!$B$4+AB20) -> 0
A21: Document Management Specialist - Mid-Level | B21: 0 | C21: =+B21+('Labor Rates'!$B$5*B21) -> 0 | D21: 0 | E21: =+D21+('Labor Rates'!$B$5*D21) -> 0 | F21: 0 | G21: =+F21+('Labor Rates'!$B$5*F21) -> 0 | I21: =SUM(B21*'Labor Rates'!$B$4+B21) -> 0 | J21: =SUM(C21*'Labor Rates'!$B$4+C21) -> 0 | K21: =SUM(D21*'Labor Rates'!$B$4+D21) -> 0 | L21: =SUM(E21*'Labor Rates'!$B$4+E21) -> 0 | M21: =SUM(F21*'Labor Rates'!$B$4+F21) -> 0 | N21: =SUM(G21*'Labor Rates'!$B$4+G21) -> 0 | P21: =SUM(I21*'Labor Rates'!$B$4+I21) -> 0 | Q21: =SUM(J21*'Labor Rates'!$B$4+J21) -> 0 | R21: =SUM(K21*'Labor Rates'!$B$4+K21) -> 0 | S21: =SUM(L21*'Labor Rates'!$B$4+L21) -> 0 | T21: =SUM(M21*'Labor Rates'!$B$4+M21) -> 0 | U21: =SUM(N21*'Labor Rates'!$B$4+N21) -> 0 | W21: =SUM(P21*'Labor Rates'!$B$4+P21) -> 0 | X21: =SUM(Q21*'Labor Rates'!$B$4+Q21) -> 0 | Y21: =SUM(R21*'Labor Rates'!$B$4+R21) -> 0 | Z21: =SUM(S21*'Labor Rates'!$B$4+S21) -> 0 | AA21: =SUM(T21*'Labor Rates'!$B$4+T21) -> 0 | AB21: =SUM(U21*'Labor Rates'!$B$4+U21) -> 0 | AD21: =SUM(W21*'Labor Rates'!$B$4+W21) -> 0 | AE21: =SUM(X21*'Labor Rates'!$B$4+X21) -> 0 | AF21: =SUM(Y21*'Labor Rates'!$B$4+Y21) -> 0 | AG21: =SUM(Z21*'Labor Rates'!$B$4+Z21) -> 0 | AH21: =SUM(AA21*'Labor Rates'!$B$4+AA21) -> 0 | AI21: =SUM(AB21*'Labor Rates'!$B$4+AB21) -> 0
A22: Document Management Specialist - Junior Level | B22: 0 | C22: =+B22+('Labor Rates'!$B$5*B22) -> 0 | D22: 0 | E22: =+D22+('Labor Rates'!$B$5*D22) -> 0 | F22: 0 | G22: =+F22+('Labor Rates'!$B$5*F22) -> 0 | I22: =SUM(B22*'Labor Rates'!$B$4+B22) -> 0 | J22: =SUM(C22*'Labor Rates'!$B$4+C22) -> 0 | K22: =SUM(D22*'Labor Rates'!$B$4+D22) -> 0 | L22: =SUM(E22*'Labor Rates'!$B$4+E22) -> 0 | M22: =SUM(F22*'Labor Rates'!$B$4+F22) -> 0 | N22: =SUM(G22*'Labor Rates'!$B$4+G22) -> 0 | P22: =SUM(I22*'Labor Rates'!$B$4+I22) -> 0 | Q22: =SUM(J22*'Labor Rates'!$B$4+J22) -> 0 | R22: =SUM(K22*'Labor Rates'!$B$4+K22) -> 0 | S22: =SUM(L22*'Labor Rates'!$B$4+L22) -> 0 | T22: =SUM(M22*'Labor Rates'!$B$4+M22) -> 0 | U22: =SUM(N22*'Labor Rates'!$B$4+N22) -> 0 | W22: =SUM(P22*'Labor Rates'!$B$4+P22) -> 0 | X22: =SUM(Q22*'Labor Rates'!$B$4+Q22) -> 0 | Y22: =SUM(R22*'Labor Rates'!$B$4+R22) -> 0 | Z22: =SUM(S22*'Labor Rates'!$B$4+S22) -> 0 | AA22: =SUM(T22*'Labor Rates'!$B$4+T22) -> 0 | AB22: =SUM(U22*'Labor Rates'!$B$4+U22) -> 0 | AD22: =SUM(W22*'Labor Rates'!$B$4+W22) -> 0 | AE22: =SUM(X22*'Labor Rates'!$B$4+X22) -> 0 | AF22: =SUM(Y22*'Labor Rates'!$B$4+Y22) -> 0 | AG22: =SUM(Z22*'Labor Rates'!$B$4+Z22) -> 0 | AH22: =SUM(AA22*'Labor Rates'!$B$4+AA22) -> 0 | AI22: =SUM(AB22*'Labor Rates'!$B$4+AB22) -> 0
A23: Financial Analyst - Senior Level | B23: 0 | C23: =+B23+('Labor Rates'!$B$5*B23) -> 0 | D23: 0 | E23: =+D23+('Labor Rates'!$B$5*D23) -> 0 | F23: 0 | G23: =+F23+('Labor Rates'!$B$5*F23) -> 0 | I23: =SUM(B23*'Labor Rates'!$B$4+B23) -> 0 | J23: =SUM(C23*'Labor Rates'!$B$4+C23) -> 0 | K23: =SUM(D23*'Labor Rates'!$B$4+D23) -> 0 | L23: =SUM(E23*'Labor Rates'!$B$4+E23) -> 0 | M23: =SUM(F23*'Labor Rates'!$B$4+F23) -> 0 | N23: =SUM(G23*'Labor Rates'!$B$4+G23) -> 0 | P23: =SUM(I23*'Labor Rates'!$B$4+I23) -> 0 | Q23: =SUM(J23*'Labor Rates'!$B$4+J23) -> 0 | R23: =SUM(K23*'Labor Rates'!$B$4+K23) -> 0 | S23: =SUM(L23*'Labor Rates'!$B$4+L23) -> 0 | T23: =SUM(M23*'Labor Rates'!$B$4+M23) -> 0 | U23: =SUM(N23*'Labor Rates'!$B$4+N23) -> 0 | W23: =SUM(P23*'Labor Rates'!$B$4+P23) -> 0 | X23: =SUM(Q23*'Labor Rates'!$B$4+Q23) -> 0 | Y23: =SUM(R23*'Labor Rates'!$B$4+R23) -> 0 | Z23: =SUM(S23*'Labor Rates'!$B$4+S23) -> 0 | AA23: =SUM(T23*'Labor Rates'!$B$4+T23) -> 0 | AB23: =SUM(U23*'Labor Rates'!$B$4+U23) -> 0 | AD23: =SUM(W23*'Labor Rates'!$B$4+W23) -> 0 | AE23: =SUM(X23*'Labor Rates'!$B$4+X23) -> 0 | AF23: =SUM(Y23*'Labor Rates'!$B$4+Y23) -> 0 | AG23: =SUM(Z23*'Labor Rates'!$B$4+Z23) -> 0 | AH23: =SUM(AA23*'Labor Rates'!$B$4+AA23) -> 0 | AI23: =SUM(AB23*'Labor Rates'!$B$4+AB23) -> 0
A24: Financial Analyst - Mid Level | B24: 0 | C24: =+B24+('Labor Rates'!$B$5*B24) -> 0 | D24: 0 | E24: =+D24+('Labor Rates'!$B$5*D24) -> 0 | F24: 0 | G24: =+F24+('Labor Rates'!$B$5*F24) -> 0 | I24: =SUM(B24*'Labor Rates'!$B$4+B24) -> 0 | J24: =SUM(C24*'Labor Rates'!$B$4+C24) -> 0 | K24: =SUM(D24*'Labor Rates'!$B$4+D24) -> 0 | L24: =SUM(E24*'Labor Rates'!$B$4+E24) -> 0 | M24: =SUM(F24*'Labor Rates'!$B$4+F24) -> 0 | N24: =SUM(G24*'Labor Rates'!$B$4+G24) -> 0 | P24: =SUM(I24*'Labor Rates'!$B$4+I24) -> 0 | Q24: =SUM(J24*'Labor Rates'!$B$4+J24) -> 0 | R24: =SUM(K24*'Labor Rates'!$B$4+K24) -> 0 | S24: =SUM(L24*'Labor Rates'!$B$4+L24) -> 0 | T24: =SUM(M24*'Labor Rates'!$B$4+M24) -> 0 | U24: =SUM(N24*'Labor Rates'!$B$4+N24) -> 0 | W24: =SUM(P24*'Labor Rates'!$B$4+P24) -> 0 | X24: =SUM(Q24*'Labor Rates'!$B$4+Q24) -> 0 | Y24: =SUM(R24*'Labor Rates'!$B$4+R24) -> 0 | Z24: =SUM(S24*'Labor Rates'!$B$4+S24) -> 0 | AA24: =SUM(T24*'Labor Rates'!$B$4+T24) -> 0 | AB24: =SUM(U24*'Labor Rates'!$B$4+U24) -> 0 | AD24: =SUM(W24*'Labor Rates'!$B$4+W24) -> 0 | AE24: =SUM(X24*'Labor Rates'!$B$4+X24) -> 0 | AF24: =SUM(Y24*'Labor Rates'!$B$4+Y24) -> 0 | AG24: =SUM(Z24*'Labor Rates'!$B$4+Z24) -> 0 | AH24: =SUM(AA24*'Labor Rates'!$B$4+AA24) -> 0 | AI24: =SUM(AB24*'Labor Rates'!$B$4+AB24) -> 0
A25: Financial Analyst - Junior Level | B25: 0 | C25: =+B25+('Labor Rates'!$B$5*B25) -> 0 | D25: 0 | E25: =+D25+('Labor Rates'!$B$5*D25) -> 0 | F25: 0 | G25: =+F25+('Labor Rates'!$B$5*F25) -> 0 | I25: =SUM(B25*'Labor Rates'!$B$4+B25) -> 0 | J25: =SUM(C25*'Labor Rates'!$B$4+C25) -> 0 | K25: =SUM(D25*'Labor Rates'!$B$4+D25) -> 0 | L25: =SUM(E25*'Labor Rates'!$B$4+E25) -> 0 | M25: =SUM(F25*'Labor Rates'!$B$4+F25) -> 0 | N25: =SUM(G25*'Labor Rates'!$B$4+G25) -> 0 | P25: =SUM(I25*'Labor Rates'!$B$4+I25) -> 0 | Q25: =SUM(J25*'Labor Rates'!$B$4+J25) -> 0 | R25: =SUM(K25*'Labor Rates'!$B$4+K25) -> 0 | S25: =SUM(L25*'Labor Rates'!$B$4+L25) -> 0 | T25: =SUM(M25*'Labor Rates'!$B$4+M25) -> 0 | U25: =SUM(N25*'Labor Rates'!$B$4+N25) -> 0 | W25: =SUM(P25*'Labor Rates'!$B$4+P25) -> 0 | X25: =SUM(Q25*'Labor Rates'!$B$4+Q25) -> 0 | Y25: =SUM(R25*'Labor Rates'!$B$4+R25) -> 0 | Z25: =SUM(S25*'Labor Rates'!$B$4+S25) -> 0 | AA25: =SUM(T25*'Labor Rates'!$B$4+T25) -> 0 | AB25: =SUM(U25*'Labor Rates'!$B$4+U25) -> 0 | AD25: =SUM(W25*'Labor Rates'!$B$4+W25) -> 0 | AE25: =SUM(X25*'Labor Rates'!$B$4+X25) -> 0 | AF25: =SUM(Y25*'Labor Rates'!$B$4+Y25) -> 0 | AG25: =SUM(Z25*'Labor Rates'!$B$4+Z25) -> 0 | AH25: =SUM(AA25*'Labor Rates'!$B$4+AA25) -> 0 | AI25: =SUM(AB25*'Labor Rates'!$B$4+AB25) -> 0
... A49: Capability Development SME - Junior Level | B49: 0 | C49: =+B49+('Labor Rates'!$B$5*B49) -> 0 | D49: 0 | E49: =+D49+('Labor Rates'!$B$5*D49) -> 0 | F49: 0 | G49: =+F49+('Labor Rates'!$B$5*F49) -> 0 | I49: =SUM(B49*'Labor Rates'!$B$4+B49) -> 0 | J49: =SUM(C49*'Labor Rates'!$B$4+C49) -> 0 | K49: =SUM(D49*'Labor Rates'!$B$4+D49) -> 0 | L49: =SUM(E49*'Labor Rates'!$B$4+E49) -> 0 | M49: =SUM(F49*'Labor Rates'!$B$4+F49) -> 0 | N49: =SUM(G49*'Labor Rates'!$B$4+G49) -> 0 | P49: =SUM(I49*'Labor Rates'!$B$4+I49) -> 0 | Q49: =SUM(J49*'Labor Rates'!$B$4+J49) -> 0 | R49: =SUM(K49*'Labor Rates'!$B$4+K49) -> 0 | S49: =SUM(L49*'Labor Rates'!$B$4+L49) -> 0 | T49: =SUM(M49*'Labor Rates'!$B$4+M49) -> 0 | U49: =SUM(N49*'Labor Rates'!$B$4+N49) -> 0 | W49: =SUM(P49*'Labor Rates'!$B$4+P49) -> 0 | X49: =SUM(Q49*'Labor Rates'!$B$4+Q49) -> 0 | Y49: =SUM(R49*'Labor Rates'!$B$4+R49) -> 0 | Z49: =SUM(S49*'Labor Rates'!$B$4+S49) -> 0 | AA49: =SUM(T49*'Labor Rates'!$B$4+T49) -> 0 | AB49: =SUM(U49*'Labor Rates'!$B$4+U49) -> 0 | AD49: =SUM(W49*'Labor Rates'!$B$4+W49) -> 0 | AE49: =SUM(X49*'Labor Rates'!$B$4+X49) -> 0 | AF49: =SUM(Y49*'Labor Rates'!$B$4+Y49) -> 0 | AG49: =SUM(Z49*'Labor Rates'!$B$4+Z49) -> 0 | AH49: =SUM(AA49*'Labor Rates'!$B$4+AA49) -> 0 | AI49: =SUM(AB49*'Labor Rates'!$B$4+AB49) -> 0
A50: Task 3 - Network, Cloud, and Cybersecurity M&A and Event and Incident Management
A51: Cybersecurity Program Manager - Senior Level | B51: 0 | C51: =+B51+('Labor Rates'!$B$5*B51) -> 0 | D51: 0 | E51: =+D51+('Labor Rates'!$B$5*D51) -> 0 | F51: 0 | G51: =+F51+('Labor Rates'!$B$5*F51) -> 0 | I51: =SUM(B51*'Labor Rates'!$B$4+B51) -> 0 | J51: =SUM(C51*'Labor Rates'!$B$4+C51) -> 0 | K51: =SUM(D51*'Labor Rates'!$B$4+D51) -> 0 | L51: =SUM(E51*'Labor Rates'!$B$4+E51) -> 0 | M51: =SUM(F51*'Labor Rates'!$B$4+F51) -> 0 | N51: =SUM(G51*'Labor Rates'!$B$4+G51) -> 0 | P51: =SUM(I51*'Labor Rates'!$B$4+I51) -> 0 | Q51: =SUM(J51*'Labor Rates'!$B$4+J51) -> 0 | R51: =SUM(K51*'Labor Rates'!$B$4+K51) -> 0 | S51: =SUM(L51*'Labor Rates'!$B$4+L51) -> 0 | T51: =SUM(M51*'Labor Rates'!$B$4+M51) -> 0 | U51: =SUM(N51*'Labor Rates'!$B$4+N51) -> 0 | W51: =SUM(P51*'Labor Rates'!$B$4+P51) -> 0 | X51: =SUM(Q51*'Labor Rates'!$B$4+Q51) -> 0 | Y51: =SUM(R51*'Labor Rates'!$B$4+R51) -> 0 | Z51: =SUM(S51*'Labor Rates'!$B$4+S51) -> 0 | AA51: =SUM(T51*'Labor Rates'!$B$4+T51) -> 0 | AB51: =SUM(U51*'Labor Rates'!$B$4+U51) -> 0 | AD51: =SUM(W51*'Labor Rates'!$B$4+W51) -> 0 | AE51: =SUM(X51*'Labor Rates'!$B$4+X51) -> 0 | AF51: =SUM(Y51*'Labor Rates'!$B$4+Y51) -> 0 | AG51: =SUM(Z51*'Labor Rates'!$B$4+Z51) -> 0 | AH51: =SUM(AA51*'Labor Rates'!$B$4+AA51) -> 0 | AI51: =SUM(AB51*'Labor Rates'!$B$4+AB51) -> 0
A52: Cybersecurity Program Manager - Mid-Level | B52: 0 | C52: =+B52+('Labor Rates'!$B$5*B52) -> 0 | D52: 0 | E52: =+D52+('Labor Rates'!$B$5*D52) -> 0 | F52: 0 | G52: =+F52+('Labor Rates'!$B$5*F52) -> 0 | I52: =SUM(B52*'Labor Rates'!$B$4+B52) -> 0 | J52: =SUM(C52*'Labor Rates'!$B$4+C52) -> 0 | K52: =SUM(D52*'Labor Rates'!$B$4+D52) -> 0 | L52: =SUM(E52*'Labor Rates'!$B$4+E52) -> 0 | M52: =SUM(F52*'Labor Rates'!$B$4+F52) -> 0 | N52: =SUM(G52*'Labor Rates'!$B$4+G52) -> 0 | P52: =SUM(I52*'Labor Rates'!$B$4+I52) -> 0 | Q52: =SUM(J52*'Labor Rates'!$B$4+J52) -> 0 | R52: =SUM(K52*'Labor Rates'!$B$4+K52) -> 0 | S52: =SUM(L52*'Labor Rates'!$B$4+L52) -> 0 | T52: =SUM(M52*'Labor Rates'!$B$4+M52) -> 0 | U52: =SUM(N52*'Labor Rates'!$B$4+N52) -> 0 | W52: =SUM(P52*'Labor Rates'!$B$4+P52) -> 0 | X52: =SUM(Q52*'Labor Rates'!$B$4+Q52) -> 0 | Y52: =SUM(R52*'Labor Rates'!$B$4+R52) -> 0 | Z52: =SUM(S52*'Labor Rates'!$B$4+S52) -> 0 | AA52: =SUM(T52*'Labor Rates'!$B$4+T52) -> 0 | AB52: =SUM(U52*'Labor Rates'!$B$4+U52) -> 0 | AD52: =SUM(W52*'Labor Rates'!$B$4+W52) -> 0 | AE52: =SUM(X52*'Labor Rates'!$B$4+X52) -> 0 | AF52: =SUM(Y52*'Labor Rates'!$B$4+Y52) -> 0 | AG52: =SUM(Z52*'Labor Rates'!$B$4+Z52) -> 0 | AH52: =SUM(AA52*'Labor Rates'!$B$4+AA52) -> 0 | AI52: =SUM(AB52*'Labor Rates'!$B$4+AB52) -> 0
A53: Cybersecurity Project Manager - Senior Level | B53: 0 | C53: =+B53+('Labor Rates'!$B$5*B53) -> 0 | D53: 0 | E53: =+D53+('Labor Rates'!$B$5*D53) -> 0 | F53: 0 | G53: =+F53+('Labor Rates'!$B$5*F53) -> 0 | I53: =SUM(B53*'Labor Rates'!$B$4+B53) -> 0 | J53: =SUM(C53*'Labor Rates'!$B$4+C53) -> 0 | K53: =SUM(D53*'Labor Rates'!$B$4+D53) -> 0 | L53: =SUM(E53*'Labor Rates'!$B$4+E53) -> 0 | M53: =SUM(F53*'Labor Rates'!$B$4+F53) -> 0 | N53: =SUM(G53*'Labor Rates'!$B$4+G53) -> 0 | P53: =SUM(I53*'Labor Rates'!$B$4+I53) -> 0 | Q53: =SUM(J53*'Labor Rates'!$B$4+J53) -> 0 | R53: =SUM(K53*'Labor Rates'!$B$4+K53) -> 0 | S53: =SUM(L53*'Labor Rates'!$B$4+L53) -> 0 | T53: =SUM(M53*'Labor Rates'!$B$4+M53) -> 0 | U53: =SUM(N53*'Labor Rates'!$B$4+N53) -> 0 | W53: =SUM(P53*'Labor Rates'!$B$4+P53) -> 0 | X53: =SUM(Q53*'Labor Rates'!$B$4+Q53) -> 0 | Y53: =SUM(R53*'Labor Rates'!$B$4+R53) -> 0 | Z53: =SUM(S53*'Labor Rates'!$B$4+S53) -> 0 | AA53: =SUM(T53*'Labor Rates'!$B$4+T53) -> 0 | AB53: =SUM(U53*'Labor Rates'!$B$4+U53) -> 0 | AD53: =SUM(W53*'Labor Rates'!$B$4+W53) -> 0 | AE53: =SUM(X53*'Labor Rates'!$B$4+X53) -> 0 | AF53: =SUM(Y53*'Labor Rates'!$B$4+Y53) -> 0 | AG53: =SUM(Z53*'Labor Rates'!$B$4+Z53) -> 0 | AH53: =SUM(AA53*'Labor Rates'!$B$4+AA53) -> 0 | AI53: =SUM(AB53*'Labor Rates'!$B$4+AB53) -> 0
A54: Cybersecurity Project Manager - Mid-Level | B54: 0 | C54: =+B54+('Labor Rates'!$B$5*B54) -> 0 | D54: 0 | E54: =+D54+('Labor Rates'!$B$5*D54) -> 0 | F54: 0 | G54: =+F54+('Labor Rates'!$B$5*F54) -> 0 | I54: =SUM(B54*'Labor Rates'!$B$4+B54) -> 0 | J54: =SUM(C54*'Labor Rates'!$B$4+C54) -> 0 | K54: =SUM(D54*'Labor Rates'!$B$4+D54) -> 0 | L54: =SUM(E54*'Labor Rates'!$B$4+E54) -> 0 | M54: =SUM(F54*'Labor Rates'!$B$4+F54) -> 0 | N54: =SUM(G54*'Labor Rates'!$B$4+G54) -> 0 | P54: =SUM(I54*'Labor Rates'!$B$4+I54) -> 0 | Q54: =SUM(J54*'Labor Rates'!$B$4+J54) -> 0 | R54: =SUM(K54*'Labor Rates'!$B$4+K54) -> 0 | S54: =SUM(L54*'Labor Rates'!$B$4+L54) -> 0 | T54: =SUM(M54*'Labor Rates'!$B$4+M54) -> 0 | U54: =SUM(N54*'Labor Rates'!$B$4+N54) -> 0 | W54: =SUM(P54*'Labor Rates'!$B$4+P54) -> 0 | X54: =SUM(Q54*'Labor Rates'!$B$4+Q54) -> 0 | Y54: =SUM(R54*'Labor Rates'!$B$4+R54) -> 0 | Z54: =SUM(S54*'Labor Rates'!$B$4+S54) -> 0 | AA54: =SUM(T54*'Labor Rates'!$B$4+T54) -> 0 | AB54: =SUM(U54*'Labor Rates'!$B$4+U54) -> 0 | AD54: =SUM(W54*'Labor Rates'!$B$4+W54) -> 0 | AE54: =SUM(X54*'Labor Rates'!$B$4+X54) -> 0 | AF54: =SUM(Y54*'Labor Rates'!$B$4+Y54) -> 0 | AG54: =SUM(Z54*'Labor Rates'!$B$4+Z54) -> 0 | AH54: =SUM(AA54*'Labor Rates'!$B$4+AA54) -> 0 | AI54: =SUM(AB54*'Labor Rates'!$B$4+AB54) -> 0
A55: Cybersecurity Project Manager - Junior Level | B55: 0 | C55: =+B55+('Labor Rates'!$B$5*B55) -> 0 | D55: 0 | E55: =+D55+('Labor Rates'!$B$5*D55) -> 0 | F55: 0 | G55: =+F55+('Labor Rates'!$B$5*F55) -> 0 | I55: =SUM(B55*'Labor Rates'!$B$4+B55) -> 0 | J55: =SUM(C55*'Labor Rates'!$B$4+C55) -> 0 | K55: =SUM(D55*'Labor Rates'!$B$4+D55) -> 0 | L55: =SUM(E55*'Labor Rates'!$B$4+E55) -> 0 | M55: =SUM(F55*'Labor Rates'!$B$4+F55) -> 0 | N55: =SUM(G55*'Labor Rates'!$B$4+G55) -> 0 | P55: =SUM(I55*'Labor Rates'!$B$4+I55) -> 0 | Q55: =SUM(J55*'Labor Rates'!$B$4+J55) -> 0 | R55: =SUM(K55*'Labor Rates'!$B$4+K55) -> 0 | S55: =SUM(L55*'Labor Rates'!$B$4+L55) -> 0 | T55: =SUM(M55*'Labor Rates'!$B$4+M55) -> 0 | U55: =SUM(N55*'Labor Rates'!$B$4+N55) -> 0 | W55: =SUM(P55*'Labor Rates'!$B$4+P55) -> 0 | X55: =SUM(Q55*'Labor Rates'!$B$4+Q55) -> 0 | Y55: =SUM(R55*'Labor Rates'!$B$4+R55) -> 0 | Z55: =SUM(S55*'Labor Rates'!$B$4+S55) -> 0 | AA55: =SUM(T55*'Labor Rates'!$B$4+T55) -> 0 | AB55: =SUM(U55*'Labor Rates'!$B$4+U55) -> 0 | AD55: =SUM(W55*'Labor Rates'!$B$4+W55) -> 0 | AE55: =SUM(X55*'Labor Rates'!$B$4+X55) -> 0 | AF55: =SUM(Y55*'Labor Rates'!$B$4+Y55) -> 0 | AG55: =SUM(Z55*'Labor Rates'!$B$4+Z55) -> 0 | AH55: =SUM(AA55*'Labor Rates'!$B$4+AA55) -> 0 | AI55: =SUM(AB55*'Labor Rates'!$B$4+AB55) -> 0
A56: Network and Infrastructure Program Manager - Senior Level | B56: 0 | C56: =+B56+('Labor Rates'!$B$5*B56) -> 0 | D56: 0 | E56: =+D56+('Labor Rates'!$B$5*D56) -> 0 | F56: 0 | G56: =+F56+('Labor Rates'!$B$5*F56) -> 0 | I56: =SUM(B56*'Labor Rates'!$B$4+B56) -> 0 | J56: =SUM(C56*'Labor Rates'!$B$4+C56) -> 0 | K56: =SUM(D56*'Labor Rates'!$B$4+D56) -> 0 | L56: =SUM(E56*'Labor Rates'!$B$4+E56) -> 0 | M56: =SUM(F56*'Labor Rates'!$B$4+F56) -> 0 | N56: =SUM(G56*'Labor Rates'!$B$4+G56) -> 0 | P56: =SUM(I56*'Labor Rates'!$B$4+I56) -> 0 | Q56: =SUM(J56*'Labor Rates'!$B$4+J56) -> 0 | R56: =SUM(K56*'Labor Rates'!$B$4+K56) -> 0 | S56: =SUM(L56*'Labor Rates'!$B$4+L56) -> 0 | T56: =SUM(M56*'Labor Rates'!$B$4+M56) -> 0 | U56: =SUM(N56*'Labor Rates'!$B$4+N56) -> 0 | W56: =SUM(P56*'Labor Rates'!$B$4+P56) -> 0 | X56: =SUM(Q56*'Labor Rates'!$B$4+Q56) -> 0 | Y56: =SUM(R56*'Labor Rates'!$B$4+R56) -> 0 | Z56: =SUM(S56*'Labor Rates'!$B$4+S56) -> 0 | AA56: =SUM(T56*'Labor Rates'!$B$4+T56) -> 0 | AB56: =SUM(U56*'Labor Rates'!$B$4+U56) -> 0 | AD56: =SUM(W56*'Labor Rates'!$B$4+W56) -> 0 | AE56: =SUM(X56*'Labor Rates'!$B$4+X56) -> 0 | AF56: =SUM(Y56*'Labor Rates'!$B$4+Y56) -> 0 | AG56: =SUM(Z56*'Labor Rates'!$B$4+Z56) -> 0 | AH56: =SUM(AA56*'Labor Rates'!$B$4+AA56) -> 0 | AI56: =SUM(AB56*'Labor Rates'!$B$4+AB56) -> 0
A57: Network and Infrastructure Program Manager - Mid-Level | B57: 0 | C57: =+B57+('Labor Rates'!$B$5*B57) -> 0 | D57: 0 | E57: =+D57+('Labor Rates'!$B$5*D57) -> 0 | F57: 0 | G57: =+F57+('Labor Rates'!$B$5*F57) -> 0 | I57: =SUM(B57*'Labor Rates'!$B$4+B57) -> 0 | J57: =SUM(C57*'Labor Rates'!$B$4+C57) -> 0 | K57: =SUM(D57*'Labor Rates'!$B$4+D57) -> 0 | L57: =SUM(E57*'Labor Rates'!$B$4+E57) -> 0 | M57: =SUM(F57*'Labor Rates'!$B$4+F57) -> 0 | N57: =SUM(G57*'Labor Rates'!$B$4+G57) -> 0 | P57: =SUM(I57*'Labor Rates'!$B$4+I57) -> 0 | Q57: =SUM(J57*'Labor Rates'!$B$4+J57) -> 0 | R57: =SUM(K57*'Labor Rates'!$B$4+K57) -> 0 | S57: =SUM(L57*'Labor Rates'!$B$4+L57) -> 0 | T57: =SUM(M57*'Labor Rates'!$B$4+M57) -> 0 | U57: =SUM(N57*'Labor Rates'!$B$4+N57) -> 0 | W57: =SUM(P57*'Labor Rates'!$B$4+P57) -> 0 | X57: =SUM(Q57*'Labor Rates'!$B$4+Q57) -> 0 | Y57: =SUM(R57*'Labor Rates'!$B$4+R57) -> 0 | Z57: =SUM(S57*'Labor Rates'!$B$4+S57) -> 0 | AA57: =SUM(T57*'Labor Rates'!$B$4+T57) -> 0 | AB57: =SUM(U57*'Labor Rates'!$B$4+U57) -> 0 | AD57: =SUM(W57*'Labor Rates'!$B$4+W57) -> 0 | AE57: =SUM(X57*'Labor Rates'!$B$4+X57) -> 0 | AF57: =SUM(Y57*'Labor Rates'!$B$4+Y57) -> 0 | AG57: =SUM(Z57*'Labor Rates'!$B$4+Z57) -> 0 | AH57: =SUM(AA57*'Labor Rates'!$B$4+AA57) -> 0 | AI57: =SUM(AB57*'Labor Rates'!$B$4+AB57) -> 0
A58: Network and Infrastructure Project Manager - Senior Level | B58: 0 | C58: =+B58+('Labor Rates'!$B$5*B58) -> 0 | D58: 0 | E58: =+D58+('Labor Rates'!$B$5*D58) -> 0 | F58: 0 | G58: =+F58+('Labor Rates'!$B$5*F58) -> 0 | I58: =SUM(B58*'Labor Rates'!$B$4+B58) -> 0 | J58: =SUM(C58*'Labor Rates'!$B$4+C58) -> 0 | K58: =SUM(D58*'Labor Rates'!$B$4+D58) -> 0 | L58: =SUM(E58*'Labor Rates'!$B$4+E58) -> 0 | M58: =SUM(F58*'Labor Rates'!$B$4+F58) -> 0 | N58: =SUM(G58*'Labor Rates'!$B$4+G58) -> 0 | P58: =SUM(I58*'Labor Rates'!$B$4+I58) -> 0 | Q58: =SUM(J58*'Labor Rates'!$B$4+J58) -> 0 | R58: =SUM(K58*'Labor Rates'!$B$4+K58) -> 0 | S58: =SUM(L58*'Labor Rates'!$B$4+L58) -> 0 | T58: =SUM(M58*'Labor Rates'!$B$4+M58) -> 0 | U58: =SUM(N58*'Labor Rates'!$B$4+N58) -> 0 | W58: =SUM(P58*'Labor Rates'!$B$4+P58) -> 0 | X58: =SUM(Q58*'Labor Rates'!$B$4+Q58) -> 0 | Y58: =SUM(R58*'Labor Rates'!$B$4+R58) -> 0 | Z58: =SUM(S58*'Labor Rates'!$B$4+S58) -> 0 | AA58: =SUM(T58*'Labor Rates'!$B$4+T58) -> 0 | AB58: =SUM(U58*'Labor Rates'!$B$4+U58) -> 0 | AD58: =SUM(W58*'Labor Rates'!$B$4+W58) -> 0 | AE58: =SUM(X58*'Labor Rates'!$B$4+X58) -> 0 | AF58: =SUM(Y58*'Labor Rates'!$B$4+Y58) -> 0 | AG58: =SUM(Z58*'Labor Rates'!$B$4+Z58) -> 0 | AH58: =SUM(AA58*'Labor Rates'!$B$4+AA58) -> 0 | AI58: =SUM(AB58*'Labor Rates'!$B$4+AB58) -> 0
A59: Network and Infrastructure Project Manager - Mid-Level | B59: 0 | C59: =+B59+('Labor Rates'!$B$5*B59) -> 0 | D59: 0 | E59: =+D59+('Labor Rates'!$B$5*D59) -> 0 | F59: 0 | G59: =+F59+('Labor Rates'!$B$5*F59) -> 0 | I59: =SUM(B59*'Labor Rates'!$B$4+B59) -> 0 | J59: =SUM(C59*'Labor Rates'!$B$4+C59) -> 0 | K59: =SUM(D59*'Labor Rates'!$B$4+D59) -> 0 | L59: =SUM(E59*'Labor Rates'!$B$4+E59) -> 0 | M59: =SUM(F59*'Labor Rates'!$B$4+F59) -> 0 | N59: =SUM(G59*'Labor Rates'!$B$4+G59) -> 0 | P59: =SUM(I59*'Labor Rates'!$B$4+I59) -> 0 | Q59: =SUM(J59*'Labor Rates'!$B$4+J59) -> 0 | R59: =SUM(K59*'Labor Rates'!$B$4+K59) -> 0 | S59: =SUM(L59*'Labor Rates'!$B$4+L59) -> 0 | T59: =SUM(M59*'Labor Rates'!$B$4+M59) -> 0 | U59: =SUM(N59*'Labor Rates'!$B$4+N59) -> 0 | W59: =SUM(P59*'Labor Rates'!$B$4+P59) -> 0 | X59: =SUM(Q59*'Labor Rates'!$B$4+Q59) -> 0 | Y59: =SUM(R59*'Labor Rates'!$B$4+R59) -> 0 | Z59: =SUM(S59*'Labor Rates'!$B$4+S59) -> 0 | AA59: =SUM(T59*'Labor Rates'!$B$4+T59) -> 0 | AB59: =SUM(U59*'Labor Rates'!$B$4+U59) -> 0 | AD59: =SUM(W59*'Labor Rates'!$B$4+W59) -> 0 | AE59: =SUM(X59*'Labor Rates'!$B$4+X59) -> 0 | AF59: =SUM(Y59*'Labor Rates'!$B$4+Y59) -> 0 | AG59: =SUM(Z59*'Labor Rates'!$B$4+Z59) -> 0 | AH59: =SUM(AA59*'Labor Rates'!$B$4+AA59) -> 0 | AI59: =SUM(AB59*'Labor Rates'!$B$4+AB59) -> 0
A60: Network and Infrastructure Project Manager - Junior Level | B60: 0 | C60: =+B60+('Labor Rates'!$B$5*B60) -> 0 | D60: 0 | E60: =+D60+('Labor Rates'!$B$5*D60) -> 0 | F60: 0 | G60: =+F60+('Labor Rates'!$B$5*F60) -> 0 | I60: =SUM(B60*'Labor Rates'!$B$4+B60) -> 0 | J60: =SUM(C60*'Labor Rates'!$B$4+C60) -> 0 | K60: =SUM(D60*'Labor Rates'!$B$4+D60) -> 0 | L60: =SUM(E60*'Labor Rates'!$B$4+E60) -> 0 | M60: =SUM(F60*'Labor Rates'!$B$4+F60) -> 0 | N60: =SUM(G60*'Labor Rates'!$B$4+G60) -> 0 | P60: =SUM(I60*'Labor Rates'!$B$4+I60) -> 0 | Q60: =SUM(J60*'Labor Rates'!$B$4+J60) -> 0 | R60: =SUM(K60*'Labor Rates'!$B$4+K60) -> 0 | S60: =SUM(L60*'Labor Rates'!$B$4+L60) -> 0 | T60: =SUM(M60*'Labor Rates'!$B$4+M60) -> 0 | U60: =SUM(N60*'Labor Rates'!$B$4+N60) -> 0 | W60: =SUM(P60*'Labor Rates'!$B$4+P60) -> 0 | X60: =SUM(Q60*'Labor Rates'!$B$4+Q60) -> 0 | Y60: =SUM(R60*'Labor Rates'!$B$4+R60) -> 0 | Z60: =SUM(S60*'Labor Rates'!$B$4+S60) -> 0 | AA60: =SUM(T60*'Labor Rates'!$B$4+T60) -> 0 | AB60: =SUM(U60*'Labor Rates'!$B$4+U60) -> 0 | AD60: =SUM(W60*'Labor Rates'!$B$4+W60) -> 0 | AE60: =SUM(X60*'Labor Rates'!$B$4+X60) -> 0 | AF60: =SUM(Y60*'Labor Rates'!$B$4+Y60) -> 0 | AG60: =SUM(Z60*'Labor Rates'!$B$4+Z60) -> 0 | AH60: =SUM(AA60*'Labor Rates'!$B$4+AA60) -> 0 | AI60: =SUM(AB60*'Labor Rates'!$B$4+AB60) -> 0
A61: Cloud and Platform Monitoring Project Manager - Senior Level | B61: 0 | C61: =+B61+('Labor Rates'!$B$5*B61) -> 0 | D61: 0 | E61: =+D61+('Labor Rates'!$B$5*D61) -> 0 | F61: 0 | G61: =+F61+('Labor Rates'!$B$5*F61) -> 0 | I61: =SUM(B61*'Labor Rates'!$B$4+B61) -> 0 | J61: =SUM(C61*'Labor Rates'!$B$4+C61) -> 0 | K61: =SUM(D61*'Labor Rates'!$B$4+D61) -> 0 | L61: =SUM(E61*'Labor Rates'!$B$4+E61) -> 0 | M61: =SUM(F61*'Labor Rates'!$B$4+F61) -> 0 | N61: =SUM(G61*'Labor Rates'!$B$4+G61) -> 0 | P61: =SUM(I61*'Labor Rates'!$B$4+I61) -> 0 | Q61: =SUM(J61*'Labor Rates'!$B$4+J61) -> 0 | R61: =SUM(K61*'Labor Rates'!$B$4+K61) -> 0 | S61: =SUM(L61*'Labor Rates'!$B$4+L61) -> 0 | T61: =SUM(M61*'Labor Rates'!$B$4+M61) -> 0 | U61: =SUM(N61*'Labor Rates'!$B$4+N61) -> 0 | W61: =SUM(P61*'Labor Rates'!$B$4+P61) -> 0 | X61: =SUM(Q61*'Labor Rates'!$B$4+Q61) -> 0 | Y61: =SUM(R61*'Labor Rates'!$B$4+R61) -> 0 | Z61: =SUM(S61*'Labor Rates'!$B$4+S61) -> 0 | AA61: =SUM(T61*'Labor Rates'!$B$4+T61) -> 0 | AB61: =SUM(U61*'Labor Rates'!$B$4+U61) -> 0 | AD61: =SUM(W61*'Labor Rates'!$B$4+W61) -> 0 | AE61: =SUM(X61*'Labor Rates'!$B$4+X61) -> 0 | AF61: =SUM(Y61*'Labor Rates'!$B$4+Y61) -> 0 | AG61: =SUM(Z61*'Labor Rates'!$B$4+Z61) -> 0 | AH61: =SUM(AA61*'Labor Rates'!$B$4+AA61) -> 0 | AI61: =SUM(AB61*'Labor Rates'!$B$4+AB61) -> 0
A62: Cloud and Platform Monitoring Project Manager - Mid-Level | B62: 0 | C62: =+B62+('Labor Rates'!$B$5*B62) -> 0 | D62: 0 | E62: =+D62+('Labor Rates'!$B$5*D62) -> 0 | F62: 0 | G62: =+F62+('Labor Rates'!$B$5*F62) -> 0 | I62: =SUM(B62*'Labor Rates'!$B$4+B62) -> 0 | J62: =SUM(C62*'Labor Rates'!$B$4+C62) -> 0 | K62: =SUM(D62*'Labor Rates'!$B$4+D62) -> 0 | L62: =SUM(E62*'Labor Rates'!$B$4+E62) -> 0 | M62: =SUM(F62*'Labor Rates'!$B$4+F62) -> 0 | N62: =SUM(G62*'Labor Rates'!$B$4+G62) -> 0 | P62: =SUM(I62*'Labor Rates'!$B$4+I62) -> 0 | Q62: =SUM(J62*'Labor Rates'!$B$4+J62) -> 0 | R62: =SUM(K62*'Labor Rates'!$B$4+K62) -> 0 | S62: =SUM(L62*'Labor Rates'!$B$4+L62) -> 0 | T62: =SUM(M62*'Labor Rates'!$B$4+M62) -> 0 | U62: =SUM(N62*'Labor Rates'!$B$4+N62) -> 0 | W62: =SUM(P62*'Labor Rates'!$B$4+P62) -> 0 | X62: =SUM(Q62*'Labor Rates'!$B$4+Q62) -> 0 | Y62: =SUM(R62*'Labor Rates'!$B$4+R62) -> 0 | Z62: =SUM(S62*'Labor Rates'!$B$4+S62) -> 0 | AA62: =SUM(T62*'Labor Rates'!$B$4+T62) -> 0 | AB62: =SUM(U62*'Labor Rates'!$B$4+U62) -> 0 | AD62: =SUM(W62*'Labor Rates'!$B$4+W62) -> 0 | AE62: =SUM(X62*'Labor Rates'!$B$4+X62) -> 0 | AF62: =SUM(Y62*'Labor Rates'!$B$4+Y62) -> 0 | AG62: =SUM(Z62*'Labor Rates'!$B$4+Z62) -> 0 | AH62: =SUM(AA62*'Labor Rates'!$B$4+AA62) -> 0 | AI62: =SUM(AB62*'Labor Rates'!$B$4+AB62) -> 0
... A166: Web Developer - Junior Level | B166: 0 | C166: =+B166+('Labor Rates'!$B$5*B166) -> 0 | D166: 0 | E166: =+D166+('Labor Rates'!$B$5*D166) -> 0 | F166: 0 | G166: =+F166+('Labor Rates'!$B$5*F166) -> 0 | I166: =SUM(B166*'Labor Rates'!$B$4+B166) -> 0 | J166: =SUM(C166*'Labor Rates'!$B$4+C166) -> 0 | K166: =SUM(D166*'Labor Rates'!$B$4+D166) -> 0 | L166: =SUM(E166*'Labor Rates'!$B$4+E166) -> 0 | M166: =SUM(F166*'Labor Rates'!$B$4+F166) -> 0 | N166: =SUM(G166*'Labor Rates'!$B$4+G166) -> 0 | P166: =SUM(I166*'Labor Rates'!$B$4+I166) -> 0 | Q166: =SUM(J166*'Labor Rates'!$B$4+J166) -> 0 | R166: =SUM(K166*'Labor Rates'!$B$4+K166) -> 0 | S166: =SUM(L166*'Labor Rates'!$B$4+L166) -> 0 | T166: =SUM(M166*'Labor Rates'!$B$4+M166) -> 0 | U166: =SUM(N166*'Labor Rates'!$B$4+N166) -> 0 | W166: =SUM(P166*'Labor Rates'!$B$4+P166) -> 0 | X166: =SUM(Q166*'Labor Rates'!$B$4+Q166) -> 0 | Y166: =SUM(R166*'Labor Rates'!$B$4+R166) -> 0 | Z166: =SUM(S166*'Labor Rates'!$B$4+S166) -> 0 | AA166: =SUM(T166*'Labor Rates'!$B$4+T166) -> 0 | AB166: =SUM(U166*'Labor Rates'!$B$4+U166) -> 0 | AD166: =SUM(W166*'Labor Rates'!$B$4+W166) -> 0 | AE166: =SUM(X166*'Labor Rates'!$B$4+X166) -> 0 | AF166: =SUM(Y166*'Labor Rates'!$B$4+Y166) -> 0 | AG166: =SUM(Z166*'Labor Rates'!$B$4+Z166) -> 0 | AH166: =SUM(AA166*'Labor Rates'!$B$4+AA166) -> 0 | AI166: =SUM(AB166*'Labor Rates'!$B$4+AB166) -> 0
A167: Task 4 - HSEN Network Infrastructure Operations and Maintenance Support
A168: Computer and Information Systems Manager - Senior Level | B168: 0 | C168: =+B168+('Labor Rates'!$B$5*B168) -> 0 | D168: 0 | E168: =+D168+('Labor Rates'!$B$5*D168) -> 0 | F168: 0 | G168: =+F168+('Labor Rates'!$B$5*F168) -> 0 | I168: =SUM(B168*'Labor Rates'!$B$4+B168) -> 0 | J168: =SUM(C168*'Labor Rates'!$B$4+C168) -> 0 | K168: =SUM(D168*'Labor Rates'!$B$4+D168) -> 0 | L168: =SUM(E168*'Labor Rates'!$B$4+E168) -> 0 | M168: =SUM(F168*'Labor Rates'!$B$4+F168) -> 0 | N168: =SUM(G168*'Labor Rates'!$B$4+G168) -> 0 | P168: =SUM(I168*'Labor Rates'!$B$4+I168) -> 0 | Q168: =SUM(J168*'Labor Rates'!$B$4+J168) -> 0 | R168: =SUM(K168*'Labor Rates'!$B$4+K168) -> 0 | S168: =SUM(L168*'Labor Rates'!$B$4+L168) -> 0 | T168: =SUM(M168*'Labor Rates'!$B$4+M168) -> 0 | U168: =SUM(N168*'Labor Rates'!$B$4+N168) -> 0 | W168: =SUM(P168*'Labor Rates'!$B$4+P168) -> 0 | X168: =SUM(Q168*'Labor Rates'!$B$4+Q168) -> 0 | Y168: =SUM(R168*'Labor Rates'!$B$4+R168) -> 0 | Z168: =SUM(S168*'Labor Rates'!$B$4+S168) -> 0 | AA168: =SUM(T168*'Labor Rates'!$B$4+T168) -> 0 | AB168: =SUM(U168*'Labor Rates'!$B$4+U168) -> 0 | AD168: =SUM(W168*'Labor Rates'!$B$4+W168) -> 0 | AE168: =SUM(X168*'Labor Rates'!$B$4+X168) -> 0 | AF168: =SUM(Y168*'Labor Rates'!$B$4+Y168) -> 0 | AG168: =SUM(Z168*'Labor Rates'!$B$4+Z168) -> 0 | AH168: =SUM(AA168*'Labor Rates'!$B$4+AA168) -> 0 | AI168: =SUM(AB168*'Labor Rates'!$B$4+AB168) -> 0
A169: Computer and Information Systems Manager - Mid-Level | B169: 0 | C169: =+B169+('Labor Rates'!$B$5*B169) -> 0 | D169: 0 | E169: =+D169+('Labor Rates'!$B$5*D169) -> 0 | F169: 0 | G169: =+F169+('Labor Rates'!$B$5*F169) -> 0 | I169: =SUM(B169*'Labor Rates'!$B$4+B169) -> 0 | J169: =SUM(C169*'Labor Rates'!$B$4+C169) -> 0 | K169: =SUM(D169*'Labor Rates'!$B$4+D169) -> 0 | L169: =SUM(E169*'Labor Rates'!$B$4+E169) -> 0 | M169: =SUM(F169*'Labor Rates'!$B$4+F169) -> 0 | N169: =SUM(G169*'Labor Rates'!$B$4+G169) -> 0 | P169: =SUM(I169*'Labor Rates'!$B$4+I169) -> 0 | Q169: =SUM(J169*'Labor Rates'!$B$4+J169) -> 0 | R169: =SUM(K169*'Labor Rates'!$B$4+K169) -> 0 | S169: =SUM(L169*'Labor Rates'!$B$4+L169) -> 0 | T169: =SUM(M169*'Labor Rates'!$B$4+M169) -> 0 | U169: =SUM(N169*'Labor Rates'!$B$4+N169) -> 0 | W169: =SUM(P169*'Labor Rates'!$B$4+P169) -> 0 | X169: =SUM(Q169*'Labor Rates'!$B$4+Q169) -> 0 | Y169: =SUM(R169*'Labor Rates'!$B$4+R169) -> 0 | Z169: =SUM(S169*'Labor Rates'!$B$4+S169) -> 0 | AA169: =SUM(T169*'Labor Rates'!$B$4+T169) -> 0 | AB169: =SUM(U169*'Labor Rates'!$B$4+U169) -> 0 | AD169: =SUM(W169*'Labor Rates'!$B$4+W169) -> 0 | AE169: =SUM(X169*'Labor Rates'!$B$4+X169) -> 0 | AF169: =SUM(Y169*'Labor Rates'!$B$4+Y169) -> 0 | AG169: =SUM(Z169*'Labor Rates'!$B$4+Z169) -> 0 | AH169: =SUM(AA169*'Labor Rates'!$B$4+AA169) -> 0 | AI169: =SUM(AB169*'Labor Rates'!$B$4+AB169) -> 0
...
